Workbook

Sheet Respuestas de formulario 1
A1: Marca temporal | B1: CAT: Primer de tot, i el teu nom? ES: Primero de todo, ¿y tu nombre? | C1: CAT: Les respostes que posaràs en aquest formulari és pel chat... (Sí, hauràs de repetir el qüestionari per respondre la teva experiència en cada CHAT/Configuració) ES: Las respuestas que pondrás en este formulario es por el chat... (Sí, tendrás que repetir el cuestionario para responder a tu experiencia en cada CHAT/Configuración) | D1: CAT: Com ha estat la teva experiència? (Com ha respost, si escrivia bé, si escrivia molt o poc) ES: ¿Cómo ha sido tu experiencia? (Como ha respondido, si escribía bien, si escribía mucho o poco) | E1: CAT: La informació que donava era informativa o no? (Si et responia exactament al que volies saber o no) ES: ¿La información que daba era informativa o no? (Si te respondía exactamente a lo que querías saber o no) | F1: CAT: Què creus que hi falta? (Quines coses pot millorar) ES: ¿Qué crees que falta? (Qué cosas puede mejorar) | G1: CAT: Alguna coseta més que vulguis aportar? :D ES: ¿Alguna cosita más que quieras aportar? :D
A2: 45489.898 | B2: anonim8 | C2: CHAT 1 | D2: Excel·lent / Excelente: (Ha respost de manera amable, sense faltes, la quantitat de paraules fetes servir eren les necessàries, no ha parlat de més. / Ha respondido de manera amable, sin faltas, la cantidad de palabras usadas eran las necesarias, no habló de más.) | E2: Sí, molt informativa / Sí, muy informativa: (Les respostes eren clares i detallades, proporcionant tota la informació necessària. / Las respuestas eran claras y detalladas, proporcionando toda la información necesaria.) | F2: Més precisió en les respostes / Más precisión en las respuestas: (El ChatBot podria proporcionar respostes més exactes i concretes. / El ChatBot podría proporcionar respuestas más exactas y concretas.)
A3: 45489.899 | B3: anonim8 | C3: CHAT 2 | D3: Bona / Buena: (Ha respost de manera correcta, amb poques faltes, la quantitat de paraules era apropiada. / Ha respondido de manera correcta, con pocas faltas, la cantidad de palabras era apropiada.) | E3: Sí, informativa: (Les respostes eren útils, però podrien ser més detallades. / Las respuestas eran útiles, pero podrían ser más detalladas.) | F3: Millor comprensió del context / Mejor comprensión del contexto: (El ChatBot podria entendre millor el context de les preguntes. / El ChatBot podría entender mejor el contexto de las preguntas.)
A4: 45489.9 | B4: anonim8 | C4: CHAT 3 | D4: Bona / Buena: (Ha respost de manera correcta, amb poques faltes, la quantitat de paraules era apropiada. / Ha respondido de manera correcta, con pocas faltas, la cantidad de palabras era apropiada.) | E4: Sí, molt informativa / Sí, muy informativa: (Les respostes eren clares i detallades, proporcionant tota la informació necessària. / Las respuestas eran claras y detalladas, proporcionando toda la información necesaria.) | F4: Millor comprensió del context / Mejor comprensión del contexto: (El ChatBot podria entendre millor el context de les preguntes. / El ChatBot podría entender mejor el contexto de las preguntas.)
A5: 45489.9 | B5: anonim8 | C5: CHAT 4 | D5: Bona / Buena: (Ha respost de manera correcta, amb poques faltes, la quantitat de paraules era apropiada. / Ha respondido de manera correcta, con pocas faltas, la cantidad de palabras era apropiada.) | E5: Sí, informativa: (Les respostes eren útils, però podrien ser més detallades. / Las respuestas eran útiles, pero podrían ser más detalladas.) | F5: Més precisió en les respostes / Más precisión en las respuestas: (El ChatBot podria proporcionar respostes més exactes i concretes. / El ChatBot podría proporcionar respuestas más exactas y concretas.)
A6: 45490.088 | B6: anonim12 | C6: CHAT 1 | D6: Escribia bien, pero excesivamente lento | E6: Sí, informativa: (Les respostes eren útils, però podrien ser més detallades. / Las respuestas eran útiles, pero podrían ser más detalladas.) | F6: Velocidad | G6: Ño
A7: 45490.089 | B7: anonim12 | C7: CHAT 2 | D7: Escribía bien, pero excesivamente lento | E7: Sí, molt informativa / Sí, muy informativa: (Les respostes eren clares i detallades, proporcionant tota la informació necessària. / Las respuestas eran claras y detalladas, proporcionando toda la información necesaria.) | F7: Més interacció natural / Más interacción natural: (El ChatBot podria tenir una conversa més fluida i semblant a la d'un humà. / El ChatBot podría tener una conversación más fluida y parecida a la de un humano.) | G7: Ño
A8: 45490.089 | B8: anonim12 | C8: CHAT 3 | D8: Escribia bien, pero excesivamente lento, ests fue la version que mas rapido respondía | E8: Sí, informativa: (Les respostes eren útils, però podrien ser més detallades. / Las respuestas eran útiles, pero podrían ser más detalladas.) | F8: Més interacció natural / Más interacción natural: (El ChatBot podria tenir una conversa més fluida i semblant a la d'un humà. / El ChatBot podría tener una conversación más fluida y parecida a la de un humano.) | G8: Ño
A9: 45490.097 | B9: anonim12 | C9: CHAT 4 | D9: Empezó respondiendo en castellano y luego pasó a Catalán, pero fue medianamente rapido | E9: Sí, molt informativa / Sí, muy informativa: (Les respostes eren clares i detallades, proporcionant tota la informació necessària. / Las respuestas eran claras y detalladas, proporcionando toda la información necesaria.) | F9: Més precisió en les respostes / Más precisión en las respuestas: (El ChatBot podria proporcionar respostes més exactes i concretes. / El ChatBot podría proporcionar respuestas más exactas y concretas.) | G9: Cuestionario repetido
A10: 45490.84 | B10: anonim10 | C10: CHAT 1 | D10: Excel·lent / Excelente: (Ha respost de manera amable, sense faltes, la quantitat de paraules fetes servir eren les necessàries, no ha parlat de més. / Ha respondido de manera amable, sin faltas, la cantidad de palabras usadas eran las necesarias, no habló de más.) | E10: Sí, molt informativa / Sí, muy informativa: (Les respostes eren clares i detallades, proporcionant tota la informació necessària. / Las respuestas eran claras y detalladas, proporcionando toda la información necesaria.) | F10: Las respuestas eran tan precisas que eran demasiado largas. | G10: No, está muy bien :D
A11: 45490.84 | B11: anonim10 | C11: CHAT 2 | D11: Excel·lent / Excelente: (Ha respost de manera amable, sense faltes, la quantitat de paraules fetes servir eren les necessàries, no ha parlat de més. / Ha respondido de manera amable, sin faltas, la cantidad de palabras usadas eran las necesarias, no habló de más.) | E11: Sí, molt informativa / Sí, muy informativa: (Les respostes eren clares i detallades, proporcionant tota la informació necessària. / Las respuestas eran claras y detalladas, proporcionando toda la información necesaria.) | F11: Respuestas muy largas | G11: Está muy bien :D
A12: 45490.842 | B12: anonim10 | C12: CHAT 4 | D12: Excel·lent / Excelente: (Ha respost de manera amable, sense faltes, la quantitat de paraules fetes servir eren les necessàries, no ha parlat de més. / Ha respondido de manera amable, sin faltas, la cantidad de palabras usadas eran las necesarias, no habló de más.) | E12: Sí, molt informativa / Sí, muy informativa: (Les respostes eren clares i detallades, proporcionant tota la informació necessària. / Las respuestas eran claras y detalladas, proporcionando toda la información necesaria.) | F12: Las respuestas son largas | G12: Que en casi todas al final del texto pone: si tienes alguna duda puedes preguntar y cosas así y en esta no, pero por lo demás está good :D
A13: 45490.845 | B13: anonim10 | C13: CHAT 3 | D13: Excel·lent / Excelente: (Ha respost de manera amable, sense faltes, la quantitat de paraules fetes servir eren les necessàries, no ha parlat de més. / Ha respondido de manera amable, sin faltas, la cantidad de palabras usadas eran las necesarias, no habló de más.) | E13: Sí, molt informativa / Sí, muy informativa: (Les respostes eren clares i detallades, proporcionant tota la informació necessària. / Las respuestas eran claras y detalladas, proporcionando toda la información necesaria.) | F13: Los textos son largos | G13: Me hace gracia que diga: bienvenido a la web del institut doctor puigvert :D
A14: 45491.662 | B14: anonim2 | C14: CHAT 1 | D14: Excel·lent / Excelente: (Ha respost de manera amable, sense faltes, la quantitat de paraules fetes servir eren les necessàries, no ha parlat de més. / Ha respondido de manera amable, sin faltas, la cantidad de palabras usadas eran las necesarias, no habló de más.) | E14: Sí, molt informativa / Sí, muy informativa: (Les respostes eren clares i detallades, proporcionant tota la informació necessària. / Las respuestas eran claras y detalladas, proporcionando toda la información necesaria.) | F14: Res, tot perfecte. | G14: Quan està generant els textos, quan hi ha alguna paraula en negreta es veuen els asteriscs mentre s’escriu la paraula, crec que només per perfeccionar i estética (i si és possible fer-ho), fer que no apareguin. I passa el mateix quan en una paraula es vol insertar un enllaç concret, es veuen els claudators etc. Però, tota la resta perfecte!
A15: 45491.683 | B15: anonim2 | C15: CHAT 2 | D15: Bona / Buena: (Ha respost de manera correcta, amb poques faltes, la quantitat de paraules era apropiada. / Ha respondido de manera correcta, con pocas faltas, la cantidad de palabras era apropiada.) | E15: Sí, molt informativa / Sí, muy informativa: (Les respostes eren clares i detallades, proporcionant tota la informació necessària. / Las respuestas eran claras y detalladas, proporcionando toda la información necesaria.) | F15: Més interacció natural / Más interacción natural: (El ChatBot podria tenir una conversa més fluida i semblant a la d'un humà. / El ChatBot podría tener una conversación más fluida y parecida a la de un humano.)
A16: 45492.988 | B16: anonim2 | C16: CHAT 4 | D16: Dolenta / Mala: (Ha respost amb moltes faltes, i la quantitat de paraules era excessiva o molt baixa. / Ha respondido con muchas faltas, y la cantidad de palabras era excesiva o muy baja.) | E16: Poc informativa / Poco informativa: (Les respostes eren vagues i no proporcionaven tota la informació necessària. / Las respuestas eran vagas y no proporcionaban toda la información necesaria.) | F16: Més precisió en les respostes / Más precisión en las respuestas: (El ChatBot podria proporcionar respostes més exactes i concretes. / El ChatBot podría proporcionar respuestas más exactas y concretas.) | G16: Mescla el català i el castellà.
A17: 45493.702 | B17: anonim5 | C17: CHAT 1 | D17: Excel·lent / Excelente: (Ha respost de manera amable, sense faltes, la quantitat de paraules fetes servir eren les necessàries, no ha parlat de més. / Ha respondido de manera amable, sin faltas, la cantidad de palabras usadas eran las necesarias, no habló de más.) | E17: Sí, molt informativa / Sí, muy informativa: (Les respostes eren clares i detallades, proporcionant tota la informació necessària. / Las respuestas eran claras y detalladas, proporcionando toda la información necesaria.) | F17: Ha estado todo perfecto, ha sido como hablar con un experto del instituto,pero ha habido algun error como que ponia el ESO, y no la ESO o que havia algun enlace que no se ha cargado y ponia: [Pàgina de petició de cita](pàgina de petició de cita) | G17: Le he echo una pregunta sobre una cosa la cual no desponia la información y me ha dado alternativas sobre como encontrar tal información, cosa que me ha parecido muy bien
A18: 45493.707 | B18: anonim5 | C18: CHAT 2 | D18: Molt Dolenta / Muy Mala: (La resposta no era comprensible o no era adequada, moltes faltes, massa paraules o massa poques. / La respuesta no era comprensible o no era adecuada, muchas faltas, demasiadas palabras o muy pocas.) | E18: Gens informativa / Nada informativa: (Les respostes no eren útils o no proporcionaven informació rellevant. / Las respuestas no eran útiles o no proporcionaban información relevante.) | F18: Més precisió en les respostes / Más precisión en las respuestas: (El ChatBot podria proporcionar respostes més exactes i concretes. / El ChatBot podría proporcionar respuestas más exactas y concretas.) | G18: Ha habido una gran diferencia entre el primer chat. Algunas respuestas han sido coherentes a pesar de que habían muchas líneas en las que era amable y muy pocas con información útil. Las preguntas más especificas no las ha sabido responder, así como el chat 1 si, y en ves de responder que no lo sabia ha empezado a escribir cosas totalmente aleatorias.
A19: 45495.524 | B19: anonim7 | C19: CHAT 1 | D19: Bona / Buena: (Ha respost de manera correcta, amb poques faltes, la quantitat de paraules era apropiada. / Ha respondido de manera correcta, con pocas faltas, la cantidad de palabras era apropiada.) | E19: Sí, molt informativa / Sí, muy informativa: (Les respostes eren clares i detallades, proporcionant tota la informació necessària. / Las respuestas eran claras y detalladas, proporcionando toda la información necesaria.) | F19: He hechado en falta un poco de interacción natural, y quizás un poco de más precisión en las respuestas.
A20: 45495.529 | B20: anonim7 | C20: CHAT 2 | D20: Dolenta / Mala: (Ha respost amb moltes faltes, i la quantitat de paraules era excessiva o molt baixa. / Ha respondido con muchas faltas, y la cantidad de palabras era excesiva o muy baja.) | E20: ha agut un problema amb el servidor | F20: Més interacció natural / Más interacción natural: (El ChatBot podria tenir una conversa més fluida i semblant a la d'un humà. / El ChatBot podría tener una conversación más fluida y parecida a la de un humano.)
A21: 45496.009 | B21: anonim7 | C21: CHAT 1 | D21: Bona / Buena: (Ha respost de manera correcta, amb poques faltes, la quantitat de paraules era apropiada. / Ha respondido de manera correcta, con pocas faltas, la cantidad de palabras era apropiada.) | E21: Sí, informativa: (Les respostes eren útils, però podrien ser més detallades. / Las respuestas eran útiles, pero podrían ser más detalladas.) | F21: Millor comprensió del context / Mejor comprensión del contexto: (El ChatBot podria entendre millor el context de les preguntes. / El ChatBot podría entender mejor el contexto de las preguntas.)
A22: 45496.423 | B22: anonim11 | C22: CHAT 1 | D22: Bona / Buena: (Ha respost de manera correcta, amb poques faltes, la quantitat de paraules era apropiada. / Ha respondido de manera correcta, con pocas faltas, la cantidad de palabras era apropiada.) | E22: Sí, molt informativa / Sí, muy informativa: (Les respostes eren clares i detallades, proporcionant tota la informació necessària. / Las respuestas eran claras y detalladas, proporcionando toda la información necesaria.) | F22: Més interacció natural / Más interacción natural: (El ChatBot podria tenir una conversa més fluida i semblant a la d'un humà. / El ChatBot podría tener una conversación más fluida y parecida a la de un humano.) | G22: Cuando le pregunto en catalán me responde en castellano.
A23: 45496.452 | B23: anonim11 | C23: CHAT 2 | D23: Error interno al iniciar la conversación | E23: Error interno al iniciar la conversación | F23: Error interno al iniciar la conversación
A24: 45496.615 | B24: anonim11 | C24: CHAT 4 | D24: Bona / Buena, pero mezcla catalán y castellano | E24: Sí, informativa: (Les respostes eren útils, però podrien ser més detallades. / Las respuestas eran útiles, pero podrían ser más detalladas.) | F24: Més precisió en les respostes / Más precisión en las respuestas: (El ChatBot podria proporcionar respostes més exactes i concretes. / El ChatBot podría proporcionar respuestas más exactas y concretas.)
A25: 45496.623 | B25: anonim11 | C25: CHAT 2 | D25: Bona / Buena: (Ha respost de manera correcta, amb poques faltes, la quantitat de paraules era apropiada. / Ha respondido de manera correcta, con pocas faltas, la cantidad de palabras era apropiada.) | E25: Sí, molt informativa / Sí, muy informativa: (Les respostes eren clares i detallades, proporcionant tota la informació necessària. / Las respuestas eran claras y detalladas, proporcionando toda la información necesaria.) | F25: Més interacció natural / Más interacción natural: (El ChatBot podria tenir una conversa més fluida i semblant a la d'un humà. / El ChatBot podría tener una conversación más fluida y parecida a la de un humano.)
A26: 45496.716 | B26: anonim4 | C26: CHAT 2 | D26: Bona / Buena: (Ha respost de manera correcta, amb poques faltes, la quantitat de paraules era apropiada. / Ha respondido de manera correcta, con pocas faltas, la cantidad de palabras era apropiada.) | E26: Sí, informativa: (Les respostes eren útils, però podrien ser més detallades. / Las respuestas eran útiles, pero podrían ser más detalladas.) | F26: Mi problema principal fue que me dio un par de errores por conexión entoces puede que sea problema mio o de que en el momento que realize la prueba alomejor los servidores tenian problemas
A27: 45496.716 | B27: anonim4 | C27: CHAT 3 | D27: Bona / Buena: (Ha respost de manera correcta, amb poques faltes, la quantitat de paraules era apropiada. / Ha respondido de manera correcta, con pocas faltas, la cantidad de palabras era apropiada.) | E27: Sí, informativa: (Les respostes eren útils, però podrien ser més detallades. / Las respuestas eran útiles, pero podrían ser más detalladas.) | F27: Millor comprensió del context / Mejor comprensión del contexto: (El ChatBot podria entendre millor el context de les preguntes. / El ChatBot podría entender mejor el contexto de las preguntas.)
A28: 45496.717 | B28: anonim4 | C28: CHAT 4 | D28: Excel·lent / Excelente: (Ha respost de manera amable, sense faltes, la quantitat de paraules fetes servir eren les necessàries, no ha parlat de més. / Ha respondido de manera amable, sin faltas, la cantidad de palabras usadas eran las necesarias, no habló de más.) | E28: Sí, molt informativa / Sí, muy informativa: (Les respostes eren clares i detallades, proporcionant tota la informació necessària. / Las respuestas eran claras y detalladas, proporcionando toda la información necesaria.) | F28: Millor comprensió del context / Mejor comprensión del contexto: (El ChatBot podria entendre millor el context de les preguntes. / El ChatBot podría entender mejor el contexto de las preguntas.)
A29: 45496.754 | B29: anonim6 | C29: CHAT 1 | D29: Comete algunos fallos gramaticales, homite informacion importante como ciertos cursos que senpueden realizar, tiene una comunicacion muy basica, le cuesta entender ciertos diminutivos como "insti" i por alguna razon tarda mas en responder cuantos mas signos de puntuacion se utilicen | E29: Homite informacion abeces, otra la da erronea , como por ejemplo homitir la existencia de los itinerario o decir que damos musica como una clase entera aparte. | F29: Falta informacion en los textos i a pesar de ello, son larguissimos, estaria bien que se redujece el texto, los errores gramaticales se han de corregir i no es capaz de responder preguntas comunes i importantes como "hablame de las instalaciones" | G29: Suerte con el TR
A30: 45496.758 | B30: anonim6 | C30: CHAT 2 | D30: Inventa o malinterpreta mucha informacion, como decir que se puede cursar hasta 4 de batchiller, comete errores gramaticales. Entiendd bien las jergas i diminitivos i en general cualquier tipo de lenguaje, da informacion irrelevante del centro como sus asociaciones con el alluntmaiento o teatro cuando solo le preguntan por los estudios disponibles, textos enormes que no dan la informacion que se pide, | E30: Homite informacion al igual que el chat 1, con la desmejora que ademas da informacion innecesario o no perteneciente a la pregunta que se le ha echo, tampoco puede contestar preguntas relacionadas con cosas como las instalaciones o de que material i aulas dispone el centro(como lo de qje tienen taller i labs etc) | F30: Le falta precision a la hora de dar informacion, corregir fallos gramaticales i redicir las.cantidades.de texto, | G30: De nuevo, suerte con el TR
A31: 45496.76 | B31: anonim6 | C31: CHAT 3 | D31: Deja morirna este bot, ne ha dado tal cantidad de problemas que no cabennen el formulario | E31: No, enserio, matalo, no hay remedio, ni siquiera he podido tener conversaciones fluidas.de lo mucho que se bugueava tenia quenentrar, hacer pregunta, responde, salir i repetir | F31: Le falta un ataud en el que descansar | G31: Por favor, acaba con el.sufrimientonde ese bot
A32: 45496.767 | B32: anonim6 | C32: CHAT 4 | D32: El bot cambia de idioma entre catalan i castellano sin aviso i sin motivo, tiene algunos errores gramaticales extraños, i usa palabras.i lenguaje exyraño, como (añada) , aún asi tiene la comunicacion mas natural.i gradable de los 3 bots(no, no cuento el 3, ese matalo) | E32: Homite alguna informacion pero no tanta com las demas, a pesar.de que sigue siendo in paragrafo relativamente largo, no lo es tanto como con los otros, i la.informacion dada.si bien es mejorable es muy aceptable, ademas proporciona informacion con relacion a la pregunta muy util, por ejemplo, le pregunte "como puedo contactar con el centro" i ademas de darme todos los datos de contacto me dio la direccion, como los demas.bots, este tampoco es capaz de.responder preguntas.sobre las instañaciones del centro | F32: Le falta pulir la informacion que da, intentar comprimirla algo mas, corregirnlos errores gramaticales i cambios de idioma, este por cierto es el bot con menos errores i el mejor de los 3 | G32: Tunometecabrasaramambiche, este es el mejor bot de todos, o por lo menos el que menos se.equivoca
A33: 45535.77 | B33: anonim3 | C33: CHAT 1 | D33: Excel·lent / Excelente: (Ha respost de manera amable, sense faltes, la quantitat de paraules fetes servir eren les necessàries, no ha parlat de més. / Ha respondido de manera amable, sin faltas, la cantidad de palabras usadas eran las necesarias, no habló de más.) | E33: Sí, molt informativa / Sí, muy informativa: (Les respostes eren clares i detallades, proporcionant tota la informació necessària. / Las respuestas eran claras y detalladas, proporcionando toda la información necesaria.) | F33: se colgo en las respuestas últimas
A34: 45535.772 | B34: anonim3 | C34: CHAT 2 | D34: Excel·lent / Excelente: (Ha respost de manera amable, sense faltes, la quantitat de paraules fetes servir eren les necessàries, no ha parlat de més. / Ha respondido de manera amable, sin faltas, la cantidad de palabras usadas eran las necesarias, no habló de más.) | E34: Sí, molt informativa / Sí, muy informativa: (Les respostes eren clares i detallades, proporcionant tota la informació necessària. / Las respuestas eran claras y detalladas, proporcionando toda la información necesaria.) | F34: Este chat se colgó pero luego se disculpo y dió las respuestas de las preguntas anteriores
A35: 45535.772 | B35: anonim3 | C35: CHAT 3 | D35: No llego a funcionar | E35: No llego a funcionar | F35: No llego a funcionar
A36: 45535.773 | B36: anonim3 | C36: CHAT 4 | D36: Excel·lent / Excelente: (Ha respost de manera amable, sense faltes, la quantitat de paraules fetes servir eren les necessàries, no ha parlat de més. / Ha respondido de manera amable, sin faltas, la cantidad de palabras usadas eran las necesarias, no habló de más.) | E36: Sí, molt informativa / Sí, muy informativa: (Les respostes eren clares i detallades, proporcionant tota la informació necessària. / Las respuestas eran claras y detalladas, proporcionando toda la información necesaria.) | F36: Las respuestas fueron muy buenas | G36: Las respuestas eran las más humanas y educadas de los chats
A37: 45538.532 | B37: anonim1 | C37: CHAT 1 | D37: Excelente, pero algunas palabras como las que están completamente en mayúsculas y algunas en negrita no las traduce al castellano y las escribe en catalán. | E37: Sí, molt informativa / Sí, muy informativa: (Les respostes eren clares i detallades, proporcionant tota la informació necessària. / Las respuestas eran claras y detalladas, proporcionando toda la información necesaria.) | F37: Todo está bien, solo cambiaria lo de que algunas palabras no las traduzca
A38: 45538.537 | B38: anonim1 | C38: CHAT 2 | D38: Bona / Buena: (Ha respost de manera correcta, amb poques faltes, la quantitat de paraules era apropiada. / Ha respondido de manera correcta, con pocas faltas, la cantidad de palabras era apropiada.) | E38: Sí, informativa: (Les respostes eren útils, però podrien ser més detallades. / Las respuestas eran útiles, pero podrían ser más detalladas.) | F38: Més precisió en les respostes / Más precisión en las respuestas: (El ChatBot podria proporcionar respostes més exactes i concretes. / El ChatBot podría proporcionar respuestas más exactas y concretas.) | G38: Algunas palabras no las traduce al castellano y las escribe en catalán.
A39: 45538.547 | B39: anonim1 | C39: CHAT 4 | D39: En algunas partes era redundante y había frases que carecían de sentido. | E39: Poco informativa, además al preguntarle por las posibles modalidades de bachilleratos me ha dicho muchas más opciones que los otros chats por lo que creo que la información era errónea. | F39: Más precisión en las respuestas y más interacción natural

Sheet puntos
A1: ='Respuestas de formulario 1'!A2 -> 45489.898 | B1: ='Respuestas de formulario 1'!B2 -> anonim8 | C1: ='Respuestas de formulario 1'!C2 -> CHAT 1 | D1: =pregunta1('Respuestas de formulario 1'!D2) -> #NAME? | E1: =pregunta2('Respuestas de formulario 1'!E2) -> #NAME? | P1: CHAT 1 | Q1: =count_for(P1,C1:C38,D1:D38) -> #NAME? | R1: =count_for(P1,C1:C38,E1:E38) -> #NAME? | T1: =SUM(Q1,R1) -> #NAME? | U1: glm4:9b-chat-q8_0
A2: ='Respuestas de formulario 1'!A3 -> 45489.899 | B2: ='Respuestas de formulario 1'!B3 -> anonim8 | C2: ='Respuestas de formulario 1'!C3 -> CHAT 2 | D2: =pregunta1('Respuestas de formulario 1'!D3) -> #NAME? | E2: =pregunta2('Respuestas de formulario 1'!E3) -> #NAME? | P2: CHAT 2 | Q2: =count_for(P2,C1:C38,D1:D38) -> #NAME? | R2: =count_for(P2,C1:C38,E1:E38) -> #NAME? | T2: =SUM(Q2,R2) -> #NAME? | U2: wizardlm2:7b-q8_0
A3: ='Respuestas de formulario 1'!A4 -> 45489.9 | B3: ='Respuestas de formulario 1'!B4 -> anonim8 | C3: ='Respuestas de formulario 1'!C4 -> CHAT 3 | D3: =pregunta1('Respuestas de formulario 1'!D4) -> #NAME? | E3: =pregunta2('Respuestas de formulario 1'!E4) -> #NAME? | P3: CHAT 3 | Q3: =count_for(P3,C1:C38,D1:D38) -> #NAME? | R3: =count_for(P3,C1:C38,E1:E38) -> #NAME? | T3: =SUM(Q3,R3) -> #NAME? | U3: phi3:14b-medium-128k-instruct-q6_K
A4: ='Respuestas de formulario 1'!A5 -> 45489.9 | B4: ='Respuestas de formulario 1'!B5 -> anonim8 | C4: ='Respuestas de formulario 1'!C5 -> CHAT 4 | D4: =pregunta1('Respuestas de formulario 1'!D5) -> #NAME? | E4: =pregunta2('Respuestas de formulario 1'!E5) -> #NAME? | P4: CHAT 4 | Q4: =count_for(P4,C1:C38,D1:D38) -> #NAME? | R4: =count_for(P4,C1:C38,E1:E38) -> #NAME? | T4: =SUM(Q4,R4) -> #NAME? | U4: internlm2:7b-chat-v2.5-q8_0
A5: ='Respuestas de formulario 1'!A6 -> 45490.088 | B5: ='Respuestas de formulario 1'!B6 -> anonim12 | C5: ='Respuestas de formulario 1'!C6 -> CHAT 1 | D5: 3 | E5: =pregunta2('Respuestas de formulario 1'!E6) -> #NAME?
A6: ='Respuestas de formulario 1'!A7 -> 45490.089 | B6: ='Respuestas de formulario 1'!B7 -> anonim12 | C6: ='Respuestas de formulario 1'!C7 -> CHAT 2 | D6: 3 | E6: =pregunta2('Respuestas de formulario 1'!E7) -> #NAME? | Q6: over 5 | R6: over 4 | T6: max 9
A7: ='Respuestas de formulario 1'!A8 -> 45490.089 | B7: ='Respuestas de formulario 1'!B8 -> anonim12 | C7: ='Respuestas de formulario 1'!C8 -> CHAT 3 | D7: 3 | E7: =pregunta2('Respuestas de formulario 1'!E8) -> #NAME? | P7: CHAT 1 | Q7: =count_for_over_n_avg(P1,C1:C1000,D1:D38) -> #NAME? | R7: =count_for_over_n_avg(P1,C1:C38,E1:E38) -> #NAME? | T7: =SUM(Q7,R7) -> #NAME? | U7: =U1 -> glm4:9b-chat-q8_0
A8: ='Respuestas de formulario 1'!A9 -> 45490.097 | B8: ='Respuestas de formulario 1'!B9 -> anonim12 | C8: ='Respuestas de formulario 1'!C9 -> CHAT 4 | D8: 3 | E8: =pregunta2('Respuestas de formulario 1'!E9) -> #NAME? | P8: CHAT 2 | Q8: =count_for_over_n_avg(P2,C1:C38,D1:D38) -> #NAME? | R8: =count_for_over_n_avg(P2,C1:C38,E1:E38) -> #NAME? | T8: =SUM(Q8,R8) -> #NAME? | U8: =U2 -> wizardlm2:7b-q8_0
A9: ='Respuestas de formulario 1'!A10 -> 45490.84 | B9: ='Respuestas de formulario 1'!B10 -> anonim10 | C9: ='Respuestas de formulario 1'!C10 -> CHAT 1 | D9: =pregunta1('Respuestas de formulario 1'!D10) -> #NAME? | E9: =pregunta2('Respuestas de formulario 1'!E10) -> #NAME? | P9: CHAT 3 | Q9: =count_for_over_n_avg(P3,C1:C38,D1:D38) -> #NAME? | R9: =count_for_over_n_avg(P3,C1:C38,E1:E38) -> #NAME? | T9: =SUM(Q9,R9) -> #NAME? | U9: =U3 -> phi3:14b-medium-128k-instruct-q6_K
A10: ='Respuestas de formulario 1'!A11 -> 45490.84 | B10: ='Respuestas de formulario 1'!B11 -> anonim10 | C10: ='Respuestas de formulario 1'!C11 -> CHAT 2 | D10: =pregunta1('Respuestas de formulario 1'!D11) -> #NAME? | E10: =pregunta2('Respuestas de formulario 1'!E11) -> #NAME? | P10: CHAT 4 | Q10: =count_for_over_n_avg(P4,C1:C38,D1:D38) -> #NAME? | R10: =count_for_over_n_avg(P4,C1:C38,E1:E38) -> #NAME? | T10: =SUM(Q10,R10) -> #NAME? | U10: =U4 -> internlm2:7b-chat-v2.5-q8_0
A11: ='Respuestas de formulario 1'!A12 -> 45490.842 | B11: ='Respuestas de formulario 1'!B12 -> anonim10 | C11: ='Respuestas de formulario 1'!C12 -> CHAT 4 | D11: =pregunta1('Respuestas de formulario 1'!D12) -> #NAME? | E11: =pregunta2('Respuestas de formulario 1'!E12) -> #NAME?
A12: ='Respuestas de formulario 1'!A13 -> 45490.845 | B12: ='Respuestas de formulario 1'!B13 -> anonim10 | C12: ='Respuestas de formulario 1'!C13 -> CHAT 3 | D12: =pregunta1('Respuestas de formulario 1'!D13) -> #NAME? | E12: =pregunta2('Respuestas de formulario 1'!E13) -> #NAME?
A13: ='Respuestas de formulario 1'!A14 -> 45491.662 | B13: ='Respuestas de formulario 1'!B14 -> anonim2 | C13: ='Respuestas de formulario 1'!C14 -> CHAT 1 | D13: =pregunta1('Respuestas de formulario 1'!D14) -> #NAME? | E13: =pregunta2('Respuestas de formulario 1'!E14) -> #NAME? | Q13: over 100 | R13: over 100 | T13: over 100
A14: ='Respuestas de formulario 1'!A15 -> 45491.683 | B14: ='Respuestas de formulario 1'!B15 -> anonim2 | C14: ='Respuestas de formulario 1'!C15 -> CHAT 2 | D14: =pregunta1('Respuestas de formulario 1'!D15) -> #NAME? | E14: =pregunta2('Respuestas de formulario 1'!E15) -> #NAME? | P14: CHAT 1 | Q14: =Q7*2*10 -> #NAME? | R14: =R7*(10/4)*10 -> #NAME? | T14: =SUM(Q14,R14)/2 -> #NAME? | U14: =U1 -> glm4:9b-chat-q8_0
A15: ='Respuestas de formulario 1'!A16 -> 45492.988 | B15: ='Respuestas de formulario 1'!B16 -> anonim2 | C15: ='Respuestas de formulario 1'!C16 -> CHAT 4 | D15: =pregunta1('Respuestas de formulario 1'!D16) -> #NAME? | E15: =pregunta2('Respuestas de formulario 1'!E16) -> #NAME? | P15: CHAT 2 | Q15: =Q8*2*10 -> #NAME? | R15: =R8*(10/4)*10 -> #NAME? | T15: =SUM(Q15,R15)/2 -> #NAME? | U15: =U2 -> wizardlm2:7b-q8_0
A16: ='Respuestas de formulario 1'!A17 -> 45493.702 | B16: ='Respuestas de formulario 1'!B17 -> anonim5 | C16: ='Respuestas de formulario 1'!C17 -> CHAT 1 | D16: =pregunta1('Respuestas de formulario 1'!D17) -> #NAME? | E16: =pregunta2('Respuestas de formulario 1'!E17) -> #NAME? | P16: CHAT 3 | Q16: =Q9*2*10 -> #NAME? | R16: =R9*(10/4)*10 -> #NAME? | T16: =SUM(Q16,R16)/2 -> #NAME? | U16: =U3 -> phi3:14b-medium-128k-instruct-q6_K
A17: ='Respuestas de formulario 1'!A18 -> 45493.707 | B17: ='Respuestas de formulario 1'!B18 -> anonim5 | C17: ='Respuestas de formulario 1'!C18 -> CHAT 2 | D17: =pregunta1('Respuestas de formulario 1'!D18) -> #NAME? | E17: =pregunta2('Respuestas de formulario 1'!E18) -> #NAME? | P17: CHAT 4 | Q17: =Q10*2*10 -> #NAME? | R17: =R10*(10/4)*10 -> #NAME? | T17: =SUM(Q17,R17)/2 -> #NAME? | U17: =U4 -> internlm2:7b-chat-v2.5-q8_0
A18: ='Respuestas de formulario 1'!A19 -> 45495.524 | B18: ='Respuestas de formulario 1'!B19 -> anonim7 | C18: ='Respuestas de formulario 1'!C19 -> CHAT 1 | D18: =pregunta1('Respuestas de formulario 1'!D19) -> #NAME? | E18: =pregunta2('Respuestas de formulario 1'!E19) -> #NAME?
A19: ='Respuestas de formulario 1'!A20 -> 45495.529 | B19: ='Respuestas de formulario 1'!B20 -> anonim7 | C19: ='Respuestas de formulario 1'!C20 -> CHAT 2 | D19: =pregunta1('Respuestas de formulario 1'!D20) -> #NAME? | E19: -1
A20: ='Respuestas de formulario 1'!A21 -> 45496.009 | B20: ='Respuestas de formulario 1'!B21 -> anonim7 | C20: ='Respuestas de formulario 1'!C21 -> CHAT 1 | D20: =pregunta1('Respuestas de formulario 1'!D21) -> #NAME? | E20: =pregunta2('Respuestas de formulario 1'!E21) -> #NAME?
A21: ='Respuestas de formulario 1'!A22 -> 45496.423 | B21: ='Respuestas de formulario 1'!B22 -> anonim11 | C21: ='Respuestas de formulario 1'!C22 -> CHAT 1 | D21: =pregunta1('Respuestas de formulario 1'!D22) -> #NAME? | E21: =pregunta2('Respuestas de formulario 1'!E22) -> #NAME?
A22: ='Respuestas de formulario 1'!A23 -> 45496.452 | B22: ='Respuestas de formulario 1'!B23 -> anonim11 | C22: ='Respuestas de formulario 1'!C23 -> CHAT 2 | D22: -1 | E22: -1
A23: ='Respuestas de formulario 1'!A24 -> 45496.615 | B23: ='Respuestas de formulario 1'!B24 -> anonim11 | C23: ='Respuestas de formulario 1'!C24 -> CHAT 4 | D23: 3 | E23: =pregunta2('Respuestas de formulario 1'!E24) -> #NAME?
A24: ='Respuestas de formulario 1'!A25 -> 45496.623 | B24: ='Respuestas de formulario 1'!B25 -> anonim11 | C24: ='Respuestas de formulario 1'!C25 -> CHAT 2 | D24: =pregunta1('Respuestas de formulario 1'!D25) -> #NAME? | E24: =pregunta2('Respuestas de formulario 1'!E25) -> #NAME?
A25: ='Respuestas de formulario 1'!A26 -> 45496.716 | B25: ='Respuestas de formulario 1'!B26 -> anonim4 | C25: ='Respuestas de formulario 1'!C26 -> CHAT 2 | D25: =pregunta1('Respuestas de formulario 1'!D26) -> #NAME? | E25: =pregunta2('Respuestas de formulario 1'!E26) -> #NAME?
A26: ='Respuestas de formulario 1'!A27 -> 45496.716 | B26: ='Respuestas de formulario 1'!B27 -> anonim4 | C26: ='Respuestas de formulario 1'!C27 -> CHAT 3 | D26: =pregunta1('Respuestas de formulario 1'!D27) -> #NAME? | E26: =pregunta2('Respuestas de formulario 1'!E27) -> #NAME?
A27: ='Respuestas de formulario 1'!A28 -> 45496.717 | B27: ='Respuestas de formulario 1'!B28 -> anonim4 | C27: ='Respuestas de formulario 1'!C28 -> CHAT 4 | D27: =pregunta1('Respuestas de formulario 1'!D28) -> #NAME? | E27: =pregunta2('Respuestas de formulario 1'!E28) -> #NAME?
A28: ='Respuestas de formulario 1'!A29 -> 45496.754 | B28: ='Respuestas de formulario 1'!B29 -> anonim6 | C28: ='Respuestas de formulario 1'!C29 -> CHAT 1 | D28: 1 | E28: 2
A29: ='Respuestas de formulario 1'!A30 -> 45496.758 | B29: ='Respuestas de formulario 1'!B30 -> anonim6 | C29: ='Respuestas de formulario 1'!C30 -> CHAT 2 | D29: 2 | E29: 1
A30: ='Respuestas de formulario 1'!A31 -> 45496.76 | B30: ='Respuestas de formulario 1'!B31 -> anonim6 | C30: ='Respuestas de formulario 1'!C31 -> CHAT 3 | D30: 0 | E30: 0
A31: ='Respuestas de formulario 1'!A32 -> 45496.767 | B31: ='Respuestas de formulario 1'!B32 -> anonim6 | C31: ='Respuestas de formulario 1'!C32 -> CHAT 4 | D31: 3 | E31: 3
A32: ='Respuestas de formulario 1'!A33 -> 45535.77 | B32: ='Respuestas de formulario 1'!B33 -> anonim3 | C32: ='Respuestas de formulario 1'!C33 -> CHAT 1 | D32: =pregunta1('Respuestas de formulario 1'!D33) -> #NAME? | E32: 2
A33: ='Respuestas de formulario 1'!A34 -> 45535.772 | B33: ='Respuestas de formulario 1'!B34 -> anonim3 | C33: ='Respuestas de formulario 1'!C34 -> CHAT 2 | D33: =pregunta1('Respuestas de formulario 1'!D34) -> #NAME? | E33: 2
A34: ='Respuestas de formulario 1'!A35 -> 45535.772 | B34: ='Respuestas de formulario 1'!B35 -> anonim3 | C34: ='Respuestas de formulario 1'!C35 -> CHAT 3 | D34: -1 | E34: -1
A35: ='Respuestas de formulario 1'!A36 -> 45535.773 | B35: ='Respuestas de formulario 1'!B36 -> anonim3 | C35: ='Respuestas de formulario 1'!C36 -> CHAT 4 | D35: =pregunta1('Respuestas de formulario 1'!D36) -> #NAME? | E35: 4
A36: ='Respuestas de formulario 1'!A37 -> 45538.532 | B36: ='Respuestas de formulario 1'!B37 -> anonim1 | C36: ='Respuestas de formulario 1'!C37 -> CHAT 1 | D36: 4 | E36: =pregunta2('Respuestas de formulario 1'!E37) -> #NAME?
A37: ='Respuestas de formulario 1'!A38 -> 45538.537 | B37: ='Respuestas de formulario 1'!B38 -> anonim1 | C37: ='Respuestas de formulario 1'!C38 -> CHAT 2 | D37: =pregunta1('Respuestas de formulario 1'!D38) -> #NAME? | E37: =pregunta2('Respuestas de formulario 1'!E38) -> #NAME?
A38: ='Respuestas de formulario 1'!A39 -> 45538.547 | B38: ='Respuestas de formulario 1'!B39 -> anonim1 | C38: ='Respuestas de formulario 1'!C39 -> CHAT 4 | D38: 2 | E38: 2
A39: ='Respuestas de formulario 1'!A47 | B39: ='Respuestas de formulario 1'!B47 | C39: ='Respuestas de formulario 1'!C47
A40: ='Respuestas de formulario 1'!A48 | B40: ='Respuestas de formulario 1'!B48 | C40: ='Respuestas de formulario 1'!C48
...
